Workbook

Sheet His
B2: Record of change
B3: Version | C3: Date | D3: PIC | E3: Change content
B4: 1.0 | C4: 45701 | D4: BangNT | E4: new

Sheet Overview
A1: Project Name | F1: Subsystem Name | K1: Screen ID | P1: Screen Name | U1: Document Name | AI1: Created Date | AN1: Author | AS1: Review Date | AX1: Reviewer | BC1: Approval Date | BH1: Approver
A2: EduLearn | F2: Courses | K2: SC001 | P2: SC Name | U2: Template_DD_v1.0.xlsx | AI2: 45701 | AN2: BangNT | AS2: 45707 | AX2: BangNT | BC2: 45701 | BH2: BangNT
A5: Summary
B7: Mô tả về
AM9: List Table
AM10: No. | AO10: Table Name | BD10: I/O
AM11: 1 | AO11: TBL_CLASS | BD11: I
B12: Sử dụng tool : https://dbdiagram.io/d | AM12: 2 | AO12: TBL_CLASS_STUDENT | BD12: I/O
AM13: 3 | AO13: TBL_CLASS_WEEKDAY | BD13: I/O
AM14: 4 | AO14: TBL_WEEKDAY
AM15: 5 | AO15: TBL_COURSE
AM16: 6 | AO16: TBL_LEVEL
AM17: 7 | AO17: TBL_CATEGORY
AM19: List File
AM20: No. | AO20: File Name | BA20: Extension | BD20: I/O
AM21: 1 | AO21: import-all-staff.xlsx | BD21: I

Sheet SQL
A1: Project Name | F1: Subsystem Name | K1: Screen ID | P1: Screen Name | U1: Document Name | AE1: Created Date | AJ1: Author | AN1: Review Date | AS1: Reviewer | AX1: Approval Date | BC1: Approver
A2: =Overview!A2 -> EduLearn | F2: =Overview!F2 -> Courses | K2: =Overview!K2 -> SC001 | P2: =Overview!P2 -> SC Name | U2: =Overview!U2 -> Template_DD_v1.0.xlsx | AE2: =Overview!AI2 -> 45701 | AJ2: =Overview!AN2 -> BangNT | AN2: =Overview!AS2 -> 45707 | AS2: =Overview!AX2 -> BangNT | AX2: =Overview!BC2 -> 45701 | BC2: =Overview!BH2 -> BangNT
A5: SQL
A14: -------------------SQL Courses------------------------------------------------------------------------------
B16: SQL_01
C17: select * from TBL_COURSE;
B21: SQL_02
C22: select * from TBL_COURSE where ID = ?;
B24: SQL_03
B25: insert into TBL_COURSE (LESSONS, TERM, LANGUAGE_ID, LEVEL_ID, CATEGORY_ID, DESCRIPTION)
B26: values (?, ?, ?, ?, ?, ?, ?, ?, ?, ?);
B29: SQL_04
B30: update TBL_COURSE
B31: set LESSONS = ?, TERM = ?, LANGUAGE_ID = ?, LEVEL_ID = ?, CATEGORY_ID = ?, DESCRIPTION = ?
B32: where ID = ?
B35: SQL_05
C36: delete from TBL_COURSE where ID = ?;
B41: SQL_06
C42: select * from TBL_COURSE where (CATEGORY_ID = ? OR ? IS NULL) AND (LEVEL_ID = ? OR ? IS NULL);
B45: SQL_07
B46: select * from TBL_LEVEL;
B48: SQL_08
B49: select * from TBL_LEVEL where ID = ?;
B52: SQL_09
B53: insert into TBL_LEVEL (CODE, NAME, DESCRIPTION)
B54: VALUES (?, ?, ?);
B56: SQL_10
B57: update TBL_LEVEL
B58: set CODE = ?, NAME = ?, DESCRIPTION = ?
B59: where ID = ?;
B62: SQL_11
... B83: delete TBL_CATEGORY where ID = ?;
A85: -------------------SQL Classes------------------------------------------------------------------------------
B87: SQL 1: getListClass
B89: select ID, NAME, START_DATE, END_DATE, PRICE
B90: from TBL_CLASS
B94: SQL 2: addClass
B95: insert into TBL_CLASS (NAME, START_DATE, END_DATE, PRICE, TEACHER_ID, COURSE_ID, DESCRIPTION, CREATED_BY, CREATED_DATE)
B96: values (%s, %s, %s, %s, %s, %s, %s, %s, NOW());
B98: SQL 3: updateClassById
...

Sheet UI
A1: Project Name | F1: Subsystem Name | K1: Screen ID | P1: Screen Name | U1: Document Name | AE1: Created Date | AJ1: Author | AN1: Review Date | AS1: Reviewer | AX1: Approval Date | BC1: Approver
A2: =Overview!A2 -> EduLearn | F2: =Overview!F2 -> Courses | K2: =Overview!K2 -> SC001 | P2: =Overview!P2 -> SC Name | U2: =Overview!U2 -> Template_DD_v1.0.xlsx | AE2: =Overview!AI2 -> 45701 | AJ2: =Overview!AN2 -> BangNT | AN2: =Overview!AS2 -> 45707 | AS2: =Overview!AX2 -> BangNT | AX2: =Overview!BC2 -> 45701 | BC2: =Overview!BH2 -> BangNT
A5: Class Diagram
C7: Sử dụng tool: https://app.diagrams.net/

Sheet SequenceDiagram
A1: Project Name | F1: Subsystem Name | K1: Screen ID | P1: Screen Name | U1: Document Name | AE1: Created Date | AJ1: Author | AN1: Review Date | AS1: Reviewer | AX1: Approval Date | BC1: Approver
A2: =Overview!A2 -> EduLearn | F2: =Overview!F2 -> Courses | K2: =Overview!K2 -> SC001 | P2: =Overview!P2 -> SC Name | U2: =Overview!U2 -> Template_DD_v1.0.xlsx | AE2: =Overview!AI2 -> 45701 | AJ2: =Overview!AN2 -> BangNT | AN2: =Overview!AS2 -> 45707 | AS2: =Overview!AX2 -> BangNT | AX2: =Overview!BC2 -> 45701 | BC2: =Overview!BH2 -> BangNT
A5: Sequence Diagram
C7: Sử dụng tool: https://app.diagrams.net/

Sheet APIs
A1: Project Name | F1: Subsystem Name | K1: Screen ID | P1: Screen Name | U1: Document Name | AE1: Created Date | AJ1: Author | AN1: Review Date | AS1: Reviewer | AX1: Approval Date | BC1: Approver
A2: =Overview!A2 -> EduLearn | F2: =Overview!F2 -> Courses | K2: =Overview!K2 -> SC001 | P2: =Overview!P2 -> SC Name | U2: =Overview!U2 -> Template_DD_v1.0.xlsx | AE2: =Overview!AI2 -> 45701 | AJ2: =Overview!AN2 -> BangNT | AN2: =Overview!AS2 -> 45707 | AS2: =Overview!AX2 -> BangNT | AX2: =Overview!BC2 -> 45701 | BC2: =Overview!BH2 -> BangNT
A5: APIs
C7: No | E7: Url | AJ7: Function | BB7: Method
C8: 1 | E8: /course/course | AJ8: addCourse | BB8: POST
C9: Parameter
E11: 1 Xử lý logic
F14: 1.1 Create class
F15: #Call Dao Method
F16: Method | L16: CourseRepository.save
F17: Parameter | L17: Course
F18: Return | L18: void
D22: 2 | E22: Return giá trị
E23: DTO Name | K23: ApiResponse
E24: # | F24: Item | U24: Source | AG24: Source Item | AS24: Note
E25: 1 | F25: message
E26: 2 | F26: code
C54: No | E54: Url | AJ54: Function | BB54: Method
C55: 2 | E55: /course/all-course | AJ55: getAllCourse | BB55: GET
C56: Parameter
E58: 1 Xử lý logic
F59: 1.1 Lấy thông tin DAO1
F60: #Call Dao Method
F61: Method | L61: getAllCourse
F62: Parameter
F63: Return | L63: List<CourseDTO>
F65: 1.2 Get all class
F66: #Call Method
F67: Method | L67: CourseRepository.findAll
F68: Parameter
F69: Return | L69: List<CourseDTO>
D73: 2 | E73: Return giá trị
E74: DTO Name | K74: ApiResponse
E75: # | F75: Item | U75: Source | AG75: Source Item | AS75: Note
E76: 1 | F76: ClassDTO | AG76: lấy từ [1.1]
C80: No | E80: Url | AJ80: Function | BB80: Method
C81: 3 | E81: /course/course/{id} | AJ81: getCourseById | BB81: GET
C82: Parameter | M82: id
E84: 1 Xử lý logic
F85: 1.1 Lấy thông tin DAO1
...

Sheet Sheet3
B2: Label
B3: Textbox
B4: Combobox
B5: DateTimePicker
B6: Button
B7: Gridview
B8: Link
B9: TabPanel
B10: Checkbox
B11: Radiobutton
B12: Icon
