Workbook

Sheet His
B2: Record of change
B3: Version | C3: Date | D3: PIC | E3: Change content
B4: 1.0 | C4: 45701 | D4: BangNT | E4: new
E5: Update

Sheet Layout
A1: Project Name | F1: Subsystem Name | K1: Screen ID | P1: Screen Name | U1: Document Name | AI1: Created Date | AN1: Author | AS1: Review Date | AX1: Reviewer | BC1: Approval Date | BH1: Approver
A2: EduLearn | F2: Courses | K2: SC001 | P2: SC Name | U2: Template_DD_v1.0.xlsx | AI2: 45701 | AN2: BangNT | AS2: 45707 | AX2: BangNT | BC2: 45701 | BH2: BangNT
A5: Summary
B7: Mô tả về
B9: figma

Sheet Overview
A1: Project Name | F1: Subsystem Name | K1: Screen ID | P1: Screen Name | U1: Document Name | AI1: Created Date | AN1: Author | AS1: Review Date | AX1: Reviewer | BC1: Approval Date | BH1: Approver
A2: EduLearn | F2: Courses | K2: SC001 | P2: SC Name | U2: Template_DD_v1.0.xlsx | AI2: 45701 | AN2: BangNT | AS2: 45707 | AX2: BangNT | BC2: 45701 | BH2: BangNT
A5: Summary
B7: Mô tả về
AM9: List Table
AM10: No. | AO10: Table Name | BD10: I/O
AM11: 1 | AO11: follows | BD11: I
B12: Sử dụng tool : https://dbdiagram.io/d | AM12: 2 | AO12: users | BD12: I/O
AM13: 3 | AO13: posts | BD13: I/O
AM19: List File
AM20: No. | AO20: File Name | BA20: Extension | BD20: I/O
AM21: 1 | AO21: import-all-staff.xlsx | BD21: I

Sheet SQL
A1: Project Name | F1: Subsystem Name | K1: Screen ID | P1: Screen Name | U1: Document Name | AE1: Created Date | AJ1: Author | AN1: Review Date | AS1: Reviewer | AX1: Approval Date | BC1: Approver
A2: =Overview!A2 -> EduLearn | F2: =Overview!F2 -> Courses | K2: =Overview!K2 -> SC001 | P2: =Overview!P2 -> SC Name | U2: =Overview!U2 -> Template_DD_v1.0.xlsx | AE2: =Overview!AI2 -> 45701 | AJ2: =Overview!AN2 -> BangNT | AN2: =Overview!AS2 -> 45707 | AS2: =Overview!AX2 -> BangNT | AX2: =Overview!BC2 -> 45701 | BC2: =Overview!BH2 -> BangNT
A5: SQL
B7: SQL_01
C8: select
C9: CO.LESSONS as LESSON
C10: from
C11: TBL_COURSE as CO
C12: where CO.LESSONS = %s order by CO.CREATED_DATE desc limit 1
B15: SQL_02
C16: select
C17: ST.FIRST_NAME as FIRST_NAME
C18: ST.LAST_NAME as LAST_NAME
C19: from
C20: TBL_STAFF as ST
C21: where ST.FIRST_NAME = %s order by ST.CREATED_DATE desc limit 1

Sheet ClassDiagram
A1: Project Name | F1: Subsystem Name | K1: Screen ID | P1: Screen Name | U1: Document Name | AE1: Created Date | AJ1: Author | AN1: Review Date | AS1: Reviewer | AX1: Approval Date | BC1: Approver
A2: =Overview!A2 -> EduLearn | F2: =Overview!F2 -> Courses | K2: =Overview!K2 -> SC001 | P2: =Overview!P2 -> SC Name | U2: =Overview!U2 -> Template_DD_v1.0.xlsx | AE2: =Overview!AI2 -> 45701 | AJ2: =Overview!AN2 -> BangNT | AN2: =Overview!AS2 -> 45707 | AS2: =Overview!AX2 -> BangNT | AX2: =Overview!BC2 -> 45701 | BC2: =Overview!BH2 -> BangNT
A5: Class Diagram
C7: Sử dụng tool: https://app.diagrams.net/

Sheet SequenceDiagram
A1: Project Name | F1: Subsystem Name | K1: Screen ID | P1: Screen Name | U1: Document Name | AE1: Created Date | AJ1: Author | AN1: Review Date | AS1: Reviewer | AX1: Approval Date | BC1: Approver
A2: =Overview!A2 -> EduLearn | F2: =Overview!F2 -> Courses | K2: =Overview!K2 -> SC001 | P2: =Overview!P2 -> SC Name | U2: =Overview!U2 -> Template_DD_v1.0.xlsx | AE2: =Overview!AI2 -> 45701 | AJ2: =Overview!AN2 -> BangNT | AN2: =Overview!AS2 -> 45707 | AS2: =Overview!AX2 -> BangNT | AX2: =Overview!BC2 -> 45701 | BC2: =Overview!BH2 -> BangNT
A5: Sequence Diagram
C7: Sử dụng tool: https://app.diagrams.net/

Sheet APIs
A1: Project Name | F1: Subsystem Name | K1: Screen ID | P1: Screen Name | U1: Document Name | AE1: Created Date | AJ1: Author | AN1: Review Date | AS1: Reviewer | AX1: Approval Date | BC1: Approver
A2: =Overview!A2 -> EduLearn | F2: =Overview!F2 -> Courses | K2: =Overview!K2 -> SC001 | P2: =Overview!P2 -> SC Name | U2: =Overview!U2 -> Template_DD_v1.0.xlsx | AE2: =Overview!AI2 -> 45701 | AJ2: =Overview!AN2 -> BangNT | AN2: =Overview!AS2 -> 45707 | AS2: =Overview!AX2 -> BangNT | AX2: =Overview!BC2 -> 45701 | BC2: =Overview!BH2 -> BangNT
A5: APIs
C7: No | E7: Url | AJ7: Function | BB7: Method
C8: 1 | E8: /course/staff-by-id | AJ8: getStaffById | BB8: GET
C9: Parameter | M9: param1
C10: Parameter | M10: param2
E12: 1 Xử lý logic
F13: 1.1 Lấy thông tin DAO1
F14: #Call Dao Method
F15: Method | L15: getCourseInfo[SQL.SQL_01]
F16: Parameter | L16: userId | AK16: parameter.param1
L17: userName | AK17: parameter.param2
F18: Return | L18: ResponseDto
F20: 1.2 Lấy tất cả user
F21: #Call Dao Method
F22: Method | L22: MUserRepository.findAll
F23: Parameter | L23: - | AK23: -
F24: Return | L24: List<MUser>
D28: 2 | E28: Return giá trị
E29: DTO Name | K29: ProjectResponse
E30: # | F30: Item | U30: Source | AG30: Source Item | AS30: Note
E31: 1 | F31: ProjectBasicResponse | U31: - | AG31: lấy từ [1.1] | AS31: -
E32: 2 | F32: email | U32: - | AG32: lấy từ [1.1] | AS32: -
C36: No | E36: Url | AJ36: Function | BB36: Method
C37: 1 | E37: /course/all-staff | AJ37: getAllStaff | BB37: GET
C38: Parameter | M38: param1
C39: Parameter | M39: param2
E41: 1 Xử lý logic
F42: 1.1 Lấy thông tin DAO1
F43: #Call Dao Method
F44: Method | L44: getStaffInfo[SQL.SQL_02]
F45: Parameter | L45: userId | AK45: parameter.param1
L46: userName | AK46: parameter.param2
F47: Return | L47: ResponseDto
F49: 1.2 Lấy tất cả user
F50: #Call Dao Method
F51: Method | L51: MUserRepository.findAll
F52: Parameter | L52: - | AK52: -
F53: Return | L53: List<MUser>
...

Sheet Sheet3
B2: Label
B3: Textbox
B4: Combobox
B5: DateTimePicker
B6: Button
B7: Gridview
B8: Link
B9: TabPanel
B10: Checkbox
B11: Radiobutton
B12: Icon
