Workbook

Sheet His
B2: Record of change
B3: Version | C3: Date | D3: PIC | E3: Change content
B4: 1.0 | C4: 45706 | D4: NamDH | E4: new
B5: 2.0 | C5: 45707 | D5: NamDH | E5: update SQL and new APIs
B6: 3.0 | C6: 45712 | D6: NamDH | E6: new UI and edit APIs
B7: 4.0 | C7: 45713 | D7: NamDH | E7: Update UI
B8: 5.0 | C8: 45714 | D8: NamDH | E8: Update SQL new APIs

Sheet Overview
A1: Project Name | F1: Subsystem Name | K1: Screen ID | P1: Screen Name | U1: Document Name | AI1: Created Date | AN1: Author | AS1: Review Date | AX1: Reviewer | BC1: Approval Date | BH1: Approver
A2: EduLearn | F2: Courses | K2: SC001 | P2: SC Name | U2: Template_DD_v1.0.xlsx | AI2: 45701 | AN2: BangNT | AS2: 45707 | AX2: BangNT | BC2: 45701 | BH2: BangNT
A5: Summary
B7: Mô tả về Student
AM9: List Table
AM10: No. | AO10: Table Name | BD10: I/O
AM11: 1 | AO11: STUDENT | BD11: I
B12: Sử dụng tool : https://dbdiagram.io/d | AM12: 2 | AO12: STUDENT_ACCOUNT | BD12: I/O
AM19: List File
AM20: No. | AO20: File Name | BA20: Extension | BD20: I/O
AM21: 1 | AO21: Student.xlsx | BD21: I

Sheet UI
A1: UI
A4: Trang xem thông tin tất cả học viên
A44: Xem thông tin học viên
A100: Đăng ký tài khoản học viên
A141: Update Info

Sheet ClassDiagram
A1: Project Name | F1: Subsystem Name | K1: Screen ID | P1: Screen Name | U1: Document Name | AE1: Created Date | AJ1: Author | AN1: Review Date | AS1: Reviewer | AX1: Approval Date | BC1: Approver
A2: =Overview!A2 -> EduLearn | F2: =Overview!F2 -> Courses | K2: =Overview!K2 -> SC001 | P2: =Overview!P2 -> SC Name | U2: =Overview!U2 -> Template_DD_v1.0.xlsx | AE2: =Overview!AI2 -> 45701 | AJ2: =Overview!AN2 -> BangNT | AN2: =Overview!AS2 -> 45707 | AS2: =Overview!AX2 -> BangNT | AX2: =Overview!BC2 -> 45701 | BC2: =Overview!BH2 -> BangNT
A5: Class Diagram
C7: Sử dụng tool: https://app.diagrams.net/

Sheet Demo APIs
B1: API
A3: API_01 :Get student theo id | G3: StudentDTO: | N3: API_02:Xóa tài khoản(change IS_ACTIVE=FALSE)
B4: URL : /student/info | H4: - firstName | O4: URL : /student
C5: - Method : GET | H5: - lastName | P5: - Method : Delete
B6: Param : | H6: - phone | O6: Param :
C7: - long id | H7: - email | P7: - no param
B8: Function | H8: - date | O8: Return: void
C9: getStudentById(Long id) | H9: - state
C10: Return: StudentDTO | H10: - city
A16: API_03:Get tất cả student | H16: StudentDTO: | N16: API_04:Update profile | X16: UpdateStudentRequest:
B17: URL : /admin/student | I17: - firstName | O17: URL : /student | Y17: - long id
C18: - Method : GET | I18: - lastName | P18: - Method : Put | Y18: - lastName
B19: Param : | I19: - phone | O19: Param : | Y19: - phone
C20: - no param | I20: - email | P20: - UpdateStudentRequest | Y20: - email
B21: Function : | I21: - date | O21: Function : | Y21: - date
C22: findAll() | I22: - state | P22: updateProfile(UpdateStudentRequest) | Y22: - state
C23: Return: List<StudentDTO> | I23: - city | P23: Return :success or fail | Y23: - city
A29: API_05:Tạo tài khoản mới cho sinh viên | L29: CreateStudentRequest: | T29: API_06 : Xem các lớp học tham gia | AA29: ClassResponse
B30: URL : /register | M30: - firstName | U30: URL : /get-class | AB30: - nameClass
C31: - Method :Post | M31: - lastName | V31: - Method:Get | AB31: - price
B32: Param : | M32: - phone | U32: Param : | AB32: - description
C33: - CreateStudentRequest | M33: - email | V33: - long id | AB33: - nameTeacher
B34: Function: | M34: - date | U34: Function
C35: createAccount(CreateStudentRequest) | M35: - state | V35: getClassByIdStudent(long id)
C36: return success or fail | M36: - city | V36: return ClassResponse
M37: - zipCode | V37: use SQL.SQL_12
M38: - loginName
M39: - password

Sheet APIs
A1: APIs
C3: No | E3: Url | AJ3: Function | BB3: Method
C4: 1 | E4: /student{id} | AJ4: getStudentById | BB4: GET
C5: Parameter | M5: id
E7: 1 Xử lý logic
F8: 1.1 Lấy thông tin DAO
F9: #Call Dao Method
F10: Method | L10: findById[SQL02]
F11: Parameter | L11: studentId | AK11: parameter.id
F12: Return | L12: Student Entity
D22: 2 | E22: Return giá trị
E23: DTO Name | K23: StudentDTO
E24: # | F24: Item | U24: Source | AG24: Source Item | AS24: Note
E25: 1 | F25: first name | AG25: lấy từ Student Entity | AS25: -
E26: 2 | F26: last name | AG26: lấy từ Student Entity | AS26: -
E27: 3 | F27: email | AG27: lấy từ Student Entity
E28: 4 | F28: phone | AG28: lấy từ Student Entity
E29: 5 | F29: date | AG29: lấy từ Student Entity
C34: No | E34: Url | AJ34: Function | BB34: Method
C35: 2 | E35: /students/{pagenumber} | AJ35: getAllStudent | BB35: GET
C36: Parameter | M36: numberpage
E38: 1 Xử lý logic
F39: 1.1 Lấy thông tin DAO
F40: #Call Dao Method
F41: Method | L41: paging[SQL_14]
F42: Parameter | L42: numberpage
F43: Return | L43: List<Student Entity>
D53: 2 | E53: Return giá trị
E54: DTO Name
E55: # | F55: Item | U55: Source | AG55: Source Item | AS55: Note
E56: 1 | F56: List<StudentDTO> | AG56: lấy từ 1.1 | AS56: -
C65: No | E65: Url | AJ65: Function | BB65: Method
C66: 3 | E66: /students/{id} | AJ66: updateStudent | BB66: PUT
C67: Parameter | M67: id,email,phone,firstname,lastname
E69: 1 Xử lý logic
F70: 1.1 Update infor Student
F71: #Call Dao Method
F72: Method | L72: findById[SQL15]
F73: Parameter | L73: id,email,phone,firstname,lastname
F74: Return | L74: boolean
...

Sheet SQL
A1: Project Name | F1: Subsystem Name | K1: Screen ID | P1: Screen Name | U1: Document Name | AE1: Created Date | AJ1: Author | AN1: Review Date | AS1: Reviewer | AX1: Approval Date | BC1: Approver
A2: =Overview!A2 -> EduLearn | F2: =Overview!F2 -> Courses | K2: =Overview!K2 -> SC001 | P2: =Overview!P2 -> SC Name | U2: =Overview!U2 -> Template_DD_v1.0.xlsx | AE2: =Overview!AI2 -> 45701 | AJ2: =Overview!AN2 -> BangNT | AN2: =Overview!AS2 -> 45707 | AS2: =Overview!AX2 -> BangNT | AX2: =Overview!BC2 -> 45701 | BC2: =Overview!BH2 -> BangNT
A5: SQL
B8: SQL_01 :Lấy thông tin tất cả học viên | AG8: SQL_14 Paging
B9: select | AG9: select
B10: * from STUDENT | AH10: FIRST_NAME as FIRSTNAME
AH11: LAST_NAME as LASTNAME
B12: SQL_02 : Lấy thông tin học viên theo id | AH12: EMAIL
B13: select | AH13: PHONE
B14: * from STUDENT | AG14: from
B15: where | AH15: STUDENT
C16: STUDENT.ID = ID | AG16: order by
AH17: ID asc
B18: SQL_03 : Lấy thông tin account của student | AG18: limit 10 offset (numberpage-1)*10
B19: select
C20: STUDENT_ACCOUNT.STUDENT_ID AS ID_STUDENT,
C21: STUDENT_ACCOUNT.LOGIN_NAME AS LOGIN_NAME,
C22: STUDENT_ACCOUNT.PASSWORD AS PASSWORD,
C23: STUDENT_ACCOUNT.IS_ACTIVE AS ACTIVE
B24: from STUDENT
B25: join
C26: STUDENT_ACCOUNT ON STUDENT.ID = STUDENT_ACCOUNT.STUDENT_ID
B28: SQL_04 Tìm thông tin học viên theo email | AG28: SQL_15
B29: select | AG29: update
C30: STUDENT.ID AS ID, | AH30: STUDENT
C31: STUDENT.DATE_BIRTH AS DATE_BIRTH, | AG31: set
C32: STUDENT.STATE AS STATE, | AH32: NAME = %S
C33: STUDENT.ZIP_CODE AS ZIP_CODE, | AH33: PHONE=%S
C34: STUDENT.STREET AS STREET, | AH34: EMAIL=%S
C35: STUDENT.FIRST_NAME AS FIRST_NAME, | AH35: FIRST_NAME=%S
C36: STUDENT.LAST_NAME AS LAST_NAME, | AH36: LAST_NAME=%S
C37: STUDENT.EMAIL AS EMAIL, | AG37: where
C38: STUDENT.PHONE AS PHONE, | AH38: ID=%X
C39: STUDENT.DESCRIPTION AS DESCRIPTION,
B40: from STUDENT | AG40: SQL_16 Tìm theo tên,email
B41: where | AG41: select
C42: STUDENT.EMAIL like '%EMAIL%' | AH42: S.FIRST_NAME AS FIRST_NAME
AH43: S.LAST_NAME as LAST_NAME
AH44: S.EMAIL as EMAIL
AH45: S.PHONE as PHONE
...

Sheet Sheet3
B2: Label
B3: Textbox
B4: Combobox
B5: DateTimePicker
B6: Button
B7: Gridview
B8: Link
B9: TabPanel
B10: Checkbox
B11: Radiobutton
B12: Icon
