Workbook

Sheet His
B2: Record of change
B3: Version | C3: Date | D3: PIC | E3: Change content
B4: 1.0 | C4: 45701 | D4: BangNT | E4: New
B5: 1.0 | C5: 2/17/2025 | D5: TuanAnh | E5: Update
B6: 2.0 | C6: 2/24/2025 | D6: TuanAnh | E6: Update UI and APIs
B7: 3.0 | C7: 2/25/2025 | D7: TuanAnh | E7: Edit UI, SQL and APIs

Sheet Overview
A1: Project Name | F1: Subsystem Name | K1: Screen ID | P1: Screen Name | U1: Document Name | AI1: Created Date | AN1: Author | AS1: Review Date | AX1: Reviewer | BC1: Approval Date | BH1: Approver
A2: EduLearn | F2: Courses | K2: SC001 | P2: SC Name | U2: Template_DD_v1.0.xlsx | AI2: 45701 | AN2: BangNT | AS2: 45707 | AX2: BangNT | BC2: 45701 | BH2: BangNT
A5: Summary
B7: Mô tả về Staff
AM9: List Table
AM10: No. | AO10: Table Name | BD10: I/O
AM11: 1 | AO11: Staff | BD11: I
B12: Sử dụng tool : https://dbdiagram.io/ | AM12: 2 | AO12: Staff_Account | BD12: I/O
AM19: List File
AM20: No. | AO20: File Name | BA20: Extension | BD20: I/O
AM21: 1 | AO21: Staff.xlsx | BD21: I

Sheet UI
A1: Project Name | F1: Subsystem Name | K1: Screen ID | P1: Screen Name | U1: Document Name | AE1: Created Date | AJ1: Author | AN1: Review Date | AS1: Reviewer | AX1: Approval Date | BC1: Approver
A2: =Overview!A2 -> EduLearn | F2: =Overview!F2 -> Courses | K2: =Overview!K2 -> SC001 | P2: =Overview!P2 -> SC Name | U2: =Overview!U2 -> Template_DD_v1.0.xlsx | AE2: =Overview!AI2 -> 45701 | AJ2: =Overview!AN2 -> BangNT | AN2: =Overview!AS2 -> 45707 | AS2: =Overview!AX2 -> BangNT | AX2: =Overview!BC2 -> 45701 | BC2: =Overview!BH2 -> BangNT
A5: UI_STAFF

Sheet SQL
A1: Project Name | F1: Subsystem Name | K1: Screen ID | P1: Screen Name | U1: Document Name | AE1: Created Date | AJ1: Author | AN1: Review Date | AS1: Reviewer | AX1: Approval Date | BC1: Approver
A2: =Overview!A2 -> EduLearn | F2: =Overview!F2 -> Courses | K2: =Overview!K2 -> SC001 | P2: =Overview!P2 -> SC Name | U2: =Overview!U2 -> Template_DD_v1.0.xlsx | AE2: =Overview!AI2 -> 45701 | AJ2: =Overview!AN2 -> BangNT | AN2: =Overview!AS2 -> 45707 | AS2: =Overview!AX2 -> BangNT | AX2: =Overview!BC2 -> 45701 | BC2: =Overview!BH2 -> BangNT
A5: SQL
B7: SQL_01: Get staff information by ID
C8: select
C9: ST.FIRST_NAME as FIRST_NAME,
C10: ST.LAST_NAME as LAST_NAME,
C11: ST.EMAIL as EMAIL,
C12: ST.PHONE as PHONE,
C13: ST.POSITION as POSITION
C14: from TBL_STAFF as ST
C15: where ST.ID = %s;
B16: SQL_02: Retrieve the list of all staff
C17: select
C18: ST.ID as STAFF_ID,
C19: ST.FIRST_NAME as FIRST_NAME,
C20: ST.LAST_NAME as LAST_NAME,
C21: ST.EMAIL as EMAIL,
C22: ST.PHONE as PHONE,
C23: ST.POSITION as POSITION,
C24: ST.CREATED_DATE as CREATED_DATE
C25: from TBL_STAFF as ST;
B26: SQL_03: Retrieve the list of staff with login accounts
C27: select
C28: ST.ID as STAFF_ID,
C29: ST.FIRST_NAME as FIRST_NAME,
C30: ST.LAST_NAME as LAST_NAME,
C31: ST.EMAIL as EMAIL,
C32: ST.PHONE as PHONE,
C33: SA.LOGIN_NAME as LOGIN_NAME,
C34: SA.IS_ACTIVE as IS_ACTIVE
C35: from TBL_STAFF as ST
C36: join TBL_STAFF_ACCOUNT as SA on ST.ID = SA.STAFF_ID;
B37: SQL_04: Get staff information along with their account details
C38: select
C39: ST.ID as STAFF_ID,
C40: ST.FIRST_NAME as FIRST_NAME,
C41: ST.LAST_NAME as LAST_NAME,
C42: ST.EMAIL as EMAIL,
C43: ST.POSITION as POSITION,
...

Sheet ClassDiagram
A1: Project Name | F1: Subsystem Name | K1: Screen ID | P1: Screen Name | U1: Document Name | AE1: Created Date | AJ1: Author | AN1: Review Date | AS1: Reviewer | AX1: Approval Date | BC1: Approver
A2: =Overview!A2 -> EduLearn | F2: =Overview!F2 -> Courses | K2: =Overview!K2 -> SC001 | P2: =Overview!P2 -> SC Name | U2: =Overview!U2 -> Template_DD_v1.0.xlsx | AE2: =Overview!AI2 -> 45701 | AJ2: =Overview!AN2 -> BangNT | AN2: =Overview!AS2 -> 45707 | AS2: =Overview!AX2 -> BangNT | AX2: =Overview!BC2 -> 45701 | BC2: =Overview!BH2 -> BangNT
A5: Class Diagram
C7: Sử dụng tool: https://app.diagrams.net/

Sheet APIs
A1: Project Name | F1: Subsystem Name | K1: Screen ID | P1: Screen Name | U1: Document Name | AE1: Created Date | AJ1: Author | AN1: Review Date | AS1: Reviewer | AX1: Approval Date | BC1: Approver
A2: =Overview!A2 -> EduLearn | F2: =Overview!F2 -> Courses | K2: =Overview!K2 -> SC001 | P2: =Overview!P2 -> SC Name | U2: =Overview!U2 -> Template_DD_v1.0.xlsx | AE2: =Overview!AI2 -> 45701 | AJ2: =Overview!AN2 -> BangNT | AN2: =Overview!AS2 -> 45707 | AS2: =Overview!AX2 -> BangNT | AX2: =Overview!BC2 -> 45701 | BC2: =Overview!BH2 -> BangNT
A5: APIs
C7: No | E7: Url | AJ7: Function | BB7: Method
C8: 1 | E8: /staff/search | AJ8: searchStaff | BB8: GET
C9: Parameter | M9: firstname
C10: Parameter | M10: lastname
C11: Parameter | M11: email
C12: Parameter | M12: phone
E14: 1 Xử lý logic
F15: 1.1 Lấy thông tin DAO1
F16: #Call Dao Method
F17: Method | L17: searchStaff[SQL.SQL_13]
F18: Parameter | L18: firstname
F19: Parameter | L19: lastname
F20: Parameter | L20: email
F21: Parameter | L21: phone
F22: Return | L22: ResponseDto
D25: 2 | E25: Return giá trị
E26: DTO Name | K26: ProjectResponse
E27: # | F27: Item | U27: Source | AG27: Source Item | AS27: Note
E28: 1 | F28: firstname | U28: - | AS28: -
E29: 2 | F29: lastname | U29: - | AS29: -
E30: 3 | F30: email
E31: 4 | F31: phone
E32: 5 | F32: position
C36: No | E36: Url | AJ36: Function | BB36: Method
C37: 2 | E37: /staff/import | AJ37: importStaff | BB37: POST
C38: Parameter | M38: firstname
C39: Parameter | M39: lastname
C40: Parameter | M40: email
C41: Parameter | M41: phone
C42: Parameter | M42: position
C43: Parameter | M43: description
C44: Parameter | M44: created_by
C45: Parameter | M45: created_date
E47: 1 Xử lý logic
F48: 1.1 Lấy thông tin DAO1
F49: #Call Dao Method
F50: Method | L50: importStaff[SQL.SQL_14]
...

Sheet SequenceDiagram
A1: Project Name | F1: Subsystem Name | K1: Screen ID | P1: Screen Name | U1: Document Name | AE1: Created Date | AJ1: Author | AN1: Review Date | AS1: Reviewer | AX1: Approval Date | BC1: Approver
A2: =Overview!A2 -> EduLearn | F2: =Overview!F2 -> Courses | K2: =Overview!K2 -> SC001 | P2: =Overview!P2 -> SC Name | U2: =Overview!U2 -> Template_DD_v1.0.xlsx | AE2: =Overview!AI2 -> 45701 | AJ2: =Overview!AN2 -> BangNT | AN2: =Overview!AS2 -> 45707 | AS2: =Overview!AX2 -> BangNT | AX2: =Overview!BC2 -> 45701 | BC2: =Overview!BH2 -> BangNT
A5: Sequence Diagram
C7: Sử dụng tool: https://app.diagrams.net/

Sheet Sheet3
B2: Label
B3: Textbox
B4: Combobox
B5: DateTimePicker
B6: Button
B7: Gridview
B8: Link
B9: TabPanel
B10: Checkbox
B11: Radiobutton
B12: Icon
