Workbook

Sheet His
B2: Record of change
B3: Version | C3: Date | D3: PIC | E3: Change content
B4: 1.0 | C4: 45701 | D4: BangNT | E4: new
B5: 1.0 | C5: 45709 | D5: Hưởng | E5: modify and add queries
B6: 1.1 | C6: 45712 | D6: Hưởng | E6: modify SQL, add UI, add APIs
B7: 1.2 | C7: 45713 | D7: Hưởng | E7: add paging, filter UI; Modify CRUD and filter APIs
B8: 1.3 | C8: 45714 | D8: Huởng | E8: update SQL, add import, export API
B9: 1.4 | C9: 45715 | D9: Hưởng | E9: modify API, SQL

Sheet Overview
A1: Project Name | F1: Subsystem Name | K1: Screen ID | P1: Screen Name | U1: Document Name | AI1: Created Date | AN1: Author | AS1: Review Date | AX1: Reviewer | BC1: Approval Date | BH1: Approver
A2: EduLearn | F2: Courses | K2: SC001 | P2: SC Name | U2: Template_DD_v1.0.xlsx | AI2: 45701 | AN2: BangNT | AS2: 45707 | AX2: BangNT | BC2: 45701 | BH2: BangNT
A5: Summary
B7: Mô tả về
AM9: List Table
AM10: No. | AO10: Table Name | BD10: I/O
AM11: 1 | AO11: Table Name | BD11: I
B12: Sử dụng tool : https://dbdiagram.io/d | AM12: 2 | AO12: Teacher | BD12: I/O
AM13: 3 | AO13: Teacher_Account | BD13: I/O
AM19: List File
AM20: No. | AO20: File Name | BA20: Extension | BD20: I/O
AM21: 1 | AO21: Teacher.xlss | BD21: I

Sheet UI
A1: Project Name | F1: Subsystem Name | K1: Screen ID | P1: Screen Name | U1: Document Name | AE1: Created Date | AJ1: Author | AN1: Review Date | AS1: Reviewer | AX1: Approval Date | BC1: Approver
A2: =Overview!A2 -> EduLearn | F2: =Overview!F2 -> Courses | K2: =Overview!K2 -> SC001 | P2: =Overview!P2 -> SC Name | U2: =Overview!U2 -> Template_DD_v1.0.xlsx | AE2: =Overview!AI2 -> 45701 | AJ2: =Overview!AN2 -> BangNT | AN2: =Overview!AS2 -> 45707 | AS2: =Overview!AX2 -> BangNT | AX2: =Overview!BC2 -> 45701 | BC2: =Overview!BH2 -> BangNT
A5: UI
A6: 1. Giao diện tổng hiển thị thông tin của danh sách giáo viên
A47: 2. Thêm giáo viên
A87: 3. Sửa thông tin của giáo viên

Sheet APIs
A1: Project Name | F1: Subsystem Name | K1: Screen ID | P1: Screen Name | U1: Document Name | AE1: Created Date | AJ1: Author | AN1: Review Date | AS1: Reviewer | AX1: Approval Date | BC1: Approver
A2: =Overview!A2 -> EduLearn | F2: =Overview!F2 -> Courses | K2: =Overview!K2 -> SC001 | P2: =Overview!P2 -> SC Name | U2: =Overview!U2 -> Template_DD_v1.0.xlsx | AE2: =Overview!AI2 -> 45701 | AJ2: =Overview!AN2 -> BangNT | AN2: =Overview!AS2 -> 45707 | AS2: =Overview!AX2 -> BangNT | AX2: =Overview!BC2 -> 45701 | BC2: =Overview!BH2 -> BangNT
A5: APIs
C7: No | E7: Url | AJ7: Function | BB7: Method
C8: 1 | E8: /teachers/{id} | AJ8: getTeacherById | BB8: GET
C9: Parameter | M9: id
E11: 1. Process logic
F12: 1.1 DAO
F13: #Call Dao Method
F14: Method | L14: getTeacherInfo[SQL.SQL_01]
F15: Parameter | L15: teacherId | AK15: parameter.id
F16: Return | L16: TeacherDto
F18: 1.2 Get teacher by id
F20: Method | L20: TeacherRepository.findById
F21: Parameter | L21: teacherId
F22: Return | L22: TeacherDto
D26: 2 | E26: Returned value
E27: DTO Name | K27: TeacherResponse
E28: # | F28: Item | U28: Source | AG28: Source Item | AS28: Note
E29: 1 | F29: first name | AG29: lấy từ [1.1] | AS29: -
E30: 2 | F30: last name | AG30: lấy từ [1.1] | AS30: -
E31: 3 | F31: email | AG31: lấy từ [1.1]
E32: 4 | F32: phone | AG32: lấy từ [1.1]
C42: No | E42: Url | AJ42: Function | BB42: Method
C43: 2 | E43: /teachers/ | AJ43: getAllTeacher | BB43: GET
C44: Parameter
E46: 1. Process logic
F47: 1.1 DAO
F48: #Call Dao Method
F49: Method | L49: getTeacherInfo[SQL.SQL_01]
F50: Parameter
F51: Return | L51: List<TeacherDto>
F53: 1.2 Get all teachers
F54: #Call Method
F55: Method | L55: TeacherRepository.findAll
F56: Parameter
F57: Return | L57: List<TeacherDto>
D61: 2 | E61: Returned value
E62: DTO Name | K62: List<TeacherDto>
E63: # | F63: Item | U63: Source | AG63: Source Item | AS63: Note
...

Sheet SQL
A1: Project Name | F1: Subsystem Name | K1: Screen ID | P1: Screen Name | U1: Document Name | AE1: Created Date | AJ1: Author | AN1: Review Date | AS1: Reviewer | AX1: Approval Date | BC1: Approver
A2: =Overview!A2 -> EduLearn | F2: =Overview!F2 -> Courses | K2: =Overview!K2 -> SC001 | P2: =Overview!P2 -> SC Name | U2: =Overview!U2 -> Template_DD_v1.0.xlsx | AE2: =Overview!AI2 -> 45701 | AJ2: =Overview!AN2 -> BangNT | AN2: =Overview!AS2 -> 45707 | AS2: =Overview!AX2 -> BangNT | AX2: =Overview!BC2 -> 45701 | BC2: =Overview!BH2 -> BangNT
A5: SQL
A6: SQL_01: Get teacher infor by ID
A7: select
A8: T.FIRST_NAME AS FIRST_NAME,
A9: T.LAST_NAME AS LAST_NAME,
A10: T.EMAIL AS EMAIL,
A11: T.PHONE AS PHONE,
A12: TA.IS_ACTIVE
A13: from
A14: TBL_TEACHER T, TBL_TEACHER_ACCOUNT TA
A15: where T.ID = %s;
A17: SQL_02: Get all teacher infor
... A55: where T.ID = %s;

Sheet ClassDiagram
A1: Project Name | F1: Subsystem Name | K1: Screen ID | P1: Screen Name | U1: Document Name | AE1: Created Date | AJ1: Author | AN1: Review Date | AS1: Reviewer | AX1: Approval Date | BC1: Approver
A2: =Overview!A2 -> EduLearn | F2: =Overview!F2 -> Courses | K2: =Overview!K2 -> SC001 | P2: =Overview!P2 -> SC Name | U2: =Overview!U2 -> Template_DD_v1.0.xlsx | AE2: =Overview!AI2 -> 45701 | AJ2: =Overview!AN2 -> BangNT | AN2: =Overview!AS2 -> 45707 | AS2: =Overview!AX2 -> BangNT | AX2: =Overview!BC2 -> 45701 | BC2: =Overview!BH2 -> BangNT
A5: Class Diagram
C7: Sử dụng tool: https://app.diagrams.net/

Sheet SequenceDiagram
A1: Project Name | F1: Subsystem Name | K1: Screen ID | P1: Screen Name | U1: Document Name | AE1: Created Date | AJ1: Author | AN1: Review Date | AS1: Reviewer | AX1: Approval Date | BC1: Approver
A2: =Overview!A2 -> EduLearn | F2: =Overview!F2 -> Courses | K2: =Overview!K2 -> SC001 | P2: =Overview!P2 -> SC Name | U2: =Overview!U2 -> Template_DD_v1.0.xlsx | AE2: =Overview!AI2 -> 45701 | AJ2: =Overview!AN2 -> BangNT | AN2: =Overview!AS2 -> 45707 | AS2: =Overview!AX2 -> BangNT | AX2: =Overview!BC2 -> 45701 | BC2: =Overview!BH2 -> BangNT
A5: Sequence Diagram
C7: Sử dụng tool: https://app.diagrams.net/

Sheet Sheet3
B2: Label
B3: Textbox
B4: Combobox
B5: DateTimePicker
B6: Button
B7: Gridview
B8: Link
B9: TabPanel
B10: Checkbox
B11: Radiobutton
B12: Icon
